{"uuid": "b34e56d0-f4b4-445a-879f-000519825726", "children": ["f4500e21-1100-49c0-a17c-033976a50164"], "befores": [{"name": "_xunit_setup_method_fixture_TestIdle", "status": "broken", "statusDetails": {"message": "selenium.common.exceptions.WebDriverException: Message: An unknown server-side error occurred while processing the command. Original error: Cannot find any free port in range 8200..8299}. Please set the available port number by providing the systemPort capability or double check the processes that are locking ports within this range and terminate these which are not needed anymore\nStacktrace:\nUnknownError: An unknown server-side error occurred while processing the command. Original error: Cannot find any free port in range 8200..8299}. Please set the available port number by providing the systemPort capability or double check the processes that are locking ports within this range and terminate these which are not needed anymore\n    at getResponseForW3CError (C:\\Users\\dd-33\\AppData\\Local\\Programs\\Appium\\resources\\app\\node_modules\\appium\\node_modules\\appium-base-driver\\lib\\protocol\\errors.js:826:9)\n    at asyncHandler (C:\\Users\\dd-33\\AppData\\Local\\Programs\\Appium\\resources\\app\\node_modules\\appium\\node_modules\\appium-base-driver\\lib\\protocol\\protocol.js:447:37)\n    at process._tickCallback (internal/process/next_tick.js:68:7)\n", "trace": "  File \"e:\\test_huahua\\venv\\lib\\site-packages\\pluggy\\_callers.py\", line 39, in _multicall\n    res = hook_impl.function(*args)\n  File \"e:\\test_huahua\\venv\\lib\\site-packages\\_pytest\\fixtures.py\", line 1129, in pytest_fixture_setup\n    result = call_fixture_func(fixturefunc, request, kwargs)\n  File \"e:\\test_huahua\\venv\\lib\\site-packages\\_pytest\\fixtures.py\", line 901, in call_fixture_func\n    fixture_result = next(generator)\n  File \"e:\\test_huahua\\venv\\lib\\site-packages\\_pytest\\python.py\", line 907, in xunit_setup_method_fixture\n    _call_with_optional_argument(func, method)\n  File \"e:\\test_huahua\\venv\\lib\\site-packages\\_pytest\\python.py\", line 788, in _call_with_optional_argument\n    func()\n  File \"E:\\test_huahua\\testcase\\test_idle.py\", line 6, in setup\n    self.idle = App().start().main().goto_idle()\n  File \"E:\\test_huahua\\page\\app.py\", line 37, in start\n    self._driver = webdriver.Remote(\"http://localhost:4723/wd/hub\", caps)\n  File \"e:\\test_huahua\\venv\\lib\\site-packages\\appium\\webdriver\\webdriver.py\", line 235, in __init__\n    options=options,\n  File \"e:\\test_huahua\\venv\\lib\\site-packages\\selenium\\webdriver\\remote\\webdriver.py\", line 286, in __init__\n    self.start_session(capabilities, browser_profile)\n  File \"e:\\test_huahua\\venv\\lib\\site-packages\\appium\\webdriver\\webdriver.py\", line 320, in start_session\n    response = self.execute(RemoteCommand.NEW_SESSION, w3c_caps)\n  File \"e:\\test_huahua\\venv\\lib\\site-packages\\selenium\\webdriver\\remote\\webdriver.py\", line 440, in execute\n    self.error_handler.check_response(response)\n  File \"e:\\test_huahua\\venv\\lib\\site-packages\\selenium\\webdriver\\remote\\errorhandler.py\", line 245, in check_response\n    raise exception_class(message, screen, stacktrace)\n"}, "start": 1703236940231, "stop": 1703236942286}], "start": 1703236940231, "stop": 1703236942321}